Traceback (most recent call last):
  File "/cluster/work/medinfmk/STCS_swiss_transplant/AI_Organ_Transplant_Matching/code/code_ernesto/comet_cluster/regressor/reg_sklearn.py", line 540, in <module>
    patients = pd.read_csv('C:/Users/Ernesto/OneDrive - ETH Zurich/Desktop/MT/COMET/synthetic_data_generation/patients.csv')
  File "/cluster/work/medinfmk/STCS_swiss_transplant/ern_env/lib/python3.10/site-packages/pandas/io/parsers/readers.py", line 1026, in read_csv
    return _read(filepath_or_buffer, kwds)
  File "/cluster/work/medinfmk/STCS_swiss_transplant/ern_env/lib/python3.10/site-packages/pandas/io/parsers/readers.py", line 620, in _read
    parser = TextFileReader(filepath_or_buffer, **kwds)
  File "/cluster/work/medinfmk/STCS_swiss_transplant/ern_env/lib/python3.10/site-packages/pandas/io/parsers/readers.py", line 1620, in __init__
    self._engine = self._make_engine(f, self.engine)
  File "/cluster/work/medinfmk/STCS_swiss_transplant/ern_env/lib/python3.10/site-packages/pandas/io/parsers/readers.py", line 1880, in _make_engine
    self.handles = get_handle(
  File "/cluster/work/medinfmk/STCS_swiss_transplant/ern_env/lib/python3.10/site-packages/pandas/io/common.py", line 873, in get_handle
    handle = open(
FileNotFoundError: [Errno 2] No such file or directory: 'C:/Users/Ernesto/OneDrive - ETH Zurich/Desktop/MT/COMET/synthetic_data_generation/patients.csv'
